Workbook

Sheet intermediate_workbook_COMPLETE
A1: Combined_Key | B1: State | C1: Year | D1: Total_Population | E1: Pop_Under_65 | F1: Pop_65_Plus | G1: Deaths_Under_65 | H1: Deaths_65_Plus | I1: Total_Flu_Deaths | J1: Death_Rate_Under_65 | K1: Death_Rate_65_Plus | L1: Death_Rate_Total | M1: Death_Rate_per_100k | N1: Pct_Under_65 | O1: Pct_65_Plus | P1: Vax_Rate_Under_65 | Q1: Vax_Rate_65_Plus
A2: Alabama_2009 | B2: Alabama | C2: 2009 | D2: 4714494.7 | E2: 4077928.8 | F2: 636565.93 | G2: 464.5 | H2: 727 | I2: 1191.5 | J2: 11.39 | K2: 114.21 | L2: 25.27 | M2: 25.27 | N2: 86.5 | O2: 13.5 | Q2: 67.4
A3: Alabama_2010 | B3: Alabama | C3: 2010 | D3: 4865573.2 | E3: 4207655.7 | F3: 657917.51 | G3: 464.5 | H3: 763 | I3: 1227.5 | J3: 11.04 | K3: 115.97 | L3: 25.23 | M3: 25.23 | N3: 86.48 | O3: 13.52 | P3: 30.6 | Q3: 68.5
A4: Alabama_2011 | B4: Alabama | C4: 2011 | D4: 5081332.6 | E4: 4382426.7 | F4: 698905.82 | G4: 443 | H4: 769.5 | I4: 1212.5 | J4: 10.11 | K4: 110.1 | L4: 23.86 | M4: 23.86 | N4: 86.25 | O4: 13.75 | P4: 29.8 | Q4: 67
A5: Alabama_2012 | B5: Alabama | C5: 2012 | D5: 4866348.8 | E5: 4185178 | F5: 681170.78 | G5: 448 | H5: 754 | I5: 1202 | J5: 10.7 | K5: 110.69 | L5: 24.7 | M5: 24.7 | N5: 86 | O5: 14 | P5: 30.6 | Q5: 66.6
A6: Alabama_2013 | B6: Alabama | C6: 2013 | D6: 4877992.6 | E6: 4179281.4 | F6: 698711.18 | G6: 499 | H6: 789.5 | I6: 1288.5 | J6: 11.94 | K6: 112.99 | L6: 26.41 | M6: 26.41 | N6: 85.68 | O6: 14.32 | P6: 29.7 | Q6: 70.6
A7: Alabama_2014 | B7: Alabama | C7: 2014 | D7: 4621409 | E7: 3956957 | F7: 664451.93 | G7: 510 | H7: 782 | I7: 1292 | J7: 12.89 | K7: 117.69 | L7: 27.96 | M7: 27.96 | N7: 85.62 | O7: 14.38 | P7: 29.2 | Q7: 65.3
A8: Alabama_2015 | B8: Alabama | C8: 2015 | D8: 4726866.2 | E8: 4022073.4 | F8: 704792.78 | G8: 498 | H8: 884 | I8: 1382 | J8: 12.38 | K8: 125.43 | L8: 29.24 | M8: 29.24 | N8: 85.09 | O8: 14.91 | P8: 27.2 | Q8: 61.1
A9: Alabama_2016 | B9: Alabama | C9: 2016 | D9: 4939042.6 | E9: 4173074.8 | F9: 765967.76 | G9: 509.5 | H9: 757 | I9: 1266.5 | J9: 12.21 | K9: 98.83 | L9: 25.64 | M9: 25.64 | N9: 84.49 | O9: 15.51 | P9: 25.7 | Q9: 63
A10: Alabama_2017 | B10: Alabama | C10: 2017 | D10: 4761712 | E10: 4010307 | F10: 751405 | G10: 500 | H10: 940 | I10: 1440 | J10: 12.47 | K10: 125.1 | L10: 30.24 | M10: 30.24 | N10: 84.22 | O10: 15.78 | P10: 24.3
A11: Alaska_2009 | B11: Alaska | C11: 2009 | D11: 735043.2 | E11: 680233.96 | F11: 54809.243 | G11: 432 | H11: 162 | I11: 594 | J11: 63.51 | K11: 295.57 | L11: 80.81 | M11: 80.81 | N11: 92.54 | O11: 7.46 | Q11: 62.6
A12: Alaska_2010 | B12: Alaska | C12: 2010 | D12: 702619.75 | E12: 648359.84 | F12: 54259.91 | G12: 432 | H12: 162 | I12: 594 | J12: 66.63 | K12: 298.56 | L12: 84.54 | M12: 84.54 | N12: 92.28 | O12: 7.72 | P12: 28.4 | Q12: 55.1
A13: Alaska_2011 | B13: Alaska | C13: 2011 | D13: 677613.16 | E13: 624306.16 | F13: 53307.001 | G13: 432 | H13: 162 | I13: 594 | J13: 69.2 | K13: 303.9 | L13: 87.66 | M13: 87.66 | N13: 92.13 | O13: 7.87 | P13: 26.8 | Q13: 49.5
A14: Alaska_2012 | B14: Alaska | C14: 2012 | D14: 675844.55 | E14: 622588.28 | F14: 53256.263 | G14: 432 | H14: 162 | I14: 594 | J14: 69.39 | K14: 304.19 | L14: 87.89 | M14: 87.89 | N14: 92.12 | O14: 7.88 | P14: 29.7 | Q14: 56
A15: Alaska_2013 | B15: Alaska | C15: 2013 | D15: 724143.8 | E15: 661009 | F15: 63134.807 | G15: 432 | H15: 162 | I15: 594 | J15: 65.35 | K15: 256.59 | L15: 82.03 | M15: 82.03 | N15: 91.28 | O15: 8.72 | P15: 30.3 | Q15: 54.3
A16: Alaska_2014 | B16: Alaska | C16: 2014 | D16: 647868.79 | E16: 589629.28 | F16: 58239.516 | G16: 432 | H16: 162 | I16: 594 | J16: 73.27 | K16: 278.16 | L16: 91.69 | M16: 91.69 | N16: 91.01 | O16: 8.99 | P16: 29.3 | Q16: 57.5
A17: Alaska_2015 | B17: Alaska | C17: 2015 | D17: 705216.96 | E17: 636479.33 | F17: 68737.628 | G17: 432 | H17: 162 | I17: 594 | J17: 67.87 | K17: 235.68 | L17: 84.23 | M17: 84.23 | N17: 90.25 | O17: 9.75 | P17: 27 | Q17: 51.5
A18: Alaska_2016 | B18: Alaska | C18: 2016 | D18: 728136.76 | E18: 651876.82 | F18: 76259.938 | G18: 432 | H18: 162 | I18: 594 | J18: 66.27 | K18: 212.43 | L18: 81.58 | M18: 81.58 | N18: 89.53 | O18: 10.47 | P18: 27.9 | Q18: 55.6
A19: Alaska_2017 | B19: Alaska | C19: 2017 | D19: 731616 | E19: 651681 | F19: 79935 | G19: 432 | H19: 162 | I19: 594 | J19: 66.29 | K19: 202.66 | L19: 81.19 | M19: 81.19 | N19: 89.07 | O19: 10.93 | P19: 27.4
A20: Arizona_2009 | B20: Arizona | C20: 2009 | D20: 6322962.5 | E20: 5508902.5 | F20: 814059.98 | G20: 478.5 | H20: 788 | I20: 1266.5 | J20: 8.69 | K20: 96.8 | L20: 20.03 | M20: 20.03 | N20: 87.13 | O20: 12.87 | Q20: 71.7
A21: Arizona_2010 | B21: Arizona | C21: 2010 | D21: 6279566.3 | E21: 5441128.7 | F21: 838437.57 | G21: 449 | H21: 596 | I21: 1045 | J21: 8.25 | K21: 71.08 | L21: 16.64 | M21: 16.64 | N21: 86.65 | O21: 13.35 | P21: 31.3 | Q21: 64.3
A22: Arizona_2011 | B22: Arizona | C22: 2011 | D22: 6299556.4 | E22: 5439685.4 | F22: 859870.99 | G22: 437.5 | H22: 558 | I22: 995.5 | J22: 8.04 | K22: 64.89 | L22: 15.8 | M22: 15.8 | N22: 86.35 | O22: 13.65 | P22: 25.7 | Q22: 58.1
A23: Arizona_2012 | B23: Arizona | C23: 2012 | D23: 6453908.1 | E23: 5558974.8 | F23: 894933.28 | G23: 438.5 | H23: 552 | I23: 990.5 | J23: 7.89 | K23: 61.68 | L23: 15.35 | M23: 15.35 | N23: 86.13 | O23: 13.87 | P23: 25.7 | Q23: 65.5
A24: Arizona_2013 | B24: Arizona | C24: 2013 | D24: 6516483.3 | E24: 5583920.8 | F24: 932562.51 | G24: 437.5 | H24: 628 | I24: 1065.5 | J24: 7.83 | K24: 67.34 | L24: 16.35 | M24: 16.35 | N24: 85.69 | O24: 14.31 | P24: 22.8 | Q24: 60.5
A25: Arizona_2014 | B25: Arizona | C25: 2014 | D25: 6548459.2 | E25: 5577448 | F25: 971011.2 | G25: 472 | H25: 584.5 | I25: 1056.5 | J25: 8.46 | K25: 60.19 | L25: 16.13 | M25: 16.13 | N25: 85.17 | O25: 14.83 | P25: 25.3 | Q25: 62.4
A26: Arizona_2015 | B26: Arizona | C26: 2015 | D26: 6533150.4 | E26: 5523563.6 | F26: 1009586.8 | G26: 439.5 | H26: 632 | I26: 1071.5 | J26: 7.96 | K26: 62.6 | L26: 16.4 | M26: 16.4 | N26: 84.55 | O26: 15.45 | P26: 25.9 | Q26: 59.4
A27: Arizona_2016 | B27: Arizona | C27: 2016 | D27: 6547976.5 | E27: 5536113.9 | F27: 1011862.6 | G27: 502.5 | H27: 667 | I27: 1169.5 | J27: 9.08 | K27: 65.92 | L27: 17.86 | M27: 17.86 | N27: 84.55 | O27: 15.45 | P27: 26.7 | Q27: 60.8
A28: Arizona_2017 | B28: Arizona | C28: 2017 | D28: 6742401 | E28: 5649633 | F28: 1092768 | G28: 453 | H28: 693 | I28: 1146 | J28: 8.02 | K28: 63.42 | L28: 17 | M28: 17 | N28: 83.79 | O28: 16.21 | P28: 21.6
A29: Arkansas_2009 | B29: Arkansas | C29: 2009 | D29: 2845308.5 | E29: 2445092.2 | F29: 400216.31 | G29: 437.5 | H29: 547.5 | I29: 985 | J29: 17.89 | K29: 136.8 | L29: 34.62 | M29: 34.62 | N29: 85.93 | O29: 14.07 | Q29: 75.4
A30: Arkansas_2010 | B30: Arkansas | C30: 2010 | D30: 3041711.8 | E30: 2605607.4 | F30: 436104.44 | G30: 432 | H30: 516 | I30: 948 | J30: 16.58 | K30: 118.32 | L30: 31.17 | M30: 31.17 | N30: 85.66 | O30: 14.34 | P30: 30.9 | Q30: 63.9
A31: Arkansas_2011 | B31: Arkansas | C31: 2011 | D31: 2970524.9 | E31: 2546498 | F31: 424026.99 | G31: 438.5 | H31: 608 | I31: 1046.5 | J31: 17.22 | K31: 143.39 | L31: 35.23 | M31: 35.23 | N31: 85.73 | O31: 14.27 | P31: 33.1 | Q31: 64.1
A32: Arkansas_2012 | B32: Arkansas | C32: 2012 | D32: 3063052.9 | E32: 2614284.8 | F32: 448768.11 | G32: 437.5 | H32: 590 | I32: 1027.5 | J32: 16.73 | K32: 131.47 | L32: 33.54 | M32: 33.54 | N32: 85.35 | O32: 14.65 | P32: 32.8 | Q32: 62.6
A33: Arkansas_2013 | B33: Arkansas | C33: 2013 | D33: 3038894 | E33: 2593175.8 | F33: 445718.18 | G33: 432 | H33: 650.5 | I33: 1082.5 | J33: 16.66 | K33: 145.94 | L33: 35.62 | M33: 35.62 | N33: 85.33 | O33: 14.67 | P33: 30.5 | Q33: 66.6
A34: Arkansas_2014 | B34: Arkansas | C34: 2014 | D34: 2953583.8 | E34: 2517489.6 | F34: 436094.22 | G34: 461.5 | H34: 530 | I34: 991.5 | J34: 18.33 | K34: 121.53 | L34: 33.57 | M34: 33.57 | N34: 85.24 | O34: 14.76 | P34: 30.3 | Q34: 69.6
A35: Arkansas_2015 | B35: Arkansas | C35: 2015 | D35: 3099489.2 | E35: 2617501.1 | F35: 481988.12 | G35: 432 | H35: 552.5 | I35: 984.5 | J35: 16.5 | K35: 114.63 | L35: 31.76 | M35: 31.76 | N35: 84.45 | O35: 15.55 | P35: 28.5 | Q35: 59.1
A36: Arkansas_2016 | B36: Arkansas | C36: 2016 | D36: 3082014.1 | E36: 2601757.4 | F36: 480256.73 | G36: 432 | H36: 518 | I36: 950 | J36: 16.6 | K36: 107.86 | L36: 30.82 | M36: 30.82 | N36: 84.42 | O36: 15.58 | P36: 30 | Q36: 62.8
A37: Arkansas_2017 | B37: Arkansas | C37: 2017 | D37: 3144162 | E37: 2648828 | F37: 495334 | G37: 438.5 | H37: 576 | I37: 1014.5 | J37: 16.55 | K37: 116.29 | L37: 32.27 | M37: 32.27 | N37: 84.25 | O37: 15.75 | P37: 23.4
A38: California_2009 | B38: California | C38: 2009 | D38: 36365426 | E38: 32389755 | F38: 3975671.4 | G38: 1311.5 | H38: 5197 | I38: 6508.5 | J38: 4.05 | K38: 130.72 | L38: 17.9 | M38: 17.9 | N38: 89.07 | O38: 10.93 | Q38: 71.8
A39: California_2010 | B39: California | C39: 2010 | D39: 36400455 | E39: 32379711 | F39: 4020744 | G39: 836 | H39: 5229 | I39: 6065 | J39: 2.58 | K39: 130.05 | L39: 16.66 | M39: 16.66 | N39: 88.95 | O39: 11.05 | P39: 27.5 | Q39: 62.5
A40: California_2011 | B40: California | C40: 2011 | D40: 37023696 | E40: 32838531 | F40: 4185164.9 | G40: 1018.5 | H40: 5338 | I40: 6356.5 | J40: 3.1 | K40: 127.55 | L40: 17.17 | M40: 17.17 | N40: 88.7 | O40: 11.3 | P40: 27.6 | Q40: 60.7
...

Sheet Chart1_Data
A1: Death Count Range | B1: 65+ Years | C1: Under 65 Years
A2: 0-500 | B2: =COUNTIFS(intermediate_workbook_COMPLETE!$H:$H,">=0",intermediate_workbook_COMPLETE!$H:$H,"<=500") -> 191 | C2: =COUNTIFS(intermediate_workbook_COMPLETE!G:G,">=0",intermediate_workbook_COMPLETE!G:G,"<=500") -> 358
A3: 501-1000 | B3: =COUNTIFS(intermediate_workbook_COMPLETE!H:H,">=501",intermediate_workbook_COMPLETE!H:H,"<=1000") -> 136 | C3: =COUNTIFS(intermediate_workbook_COMPLETE!G:G,">=501",intermediate_workbook_COMPLETE!G:G,"<=1000") -> 93
A4: 1001-1500 | B4: =COUNTIFS(intermediate_workbook_COMPLETE!H:H,">=1001",intermediate_workbook_COMPLETE!H:H,"<=1500") -> 59 | C4: =COUNTIFS(intermediate_workbook_COMPLETE!G:G,">=1001",intermediate_workbook_COMPLETE!G:G,"<=1500") -> 7
A5: 1501-2000 | B5: =COUNTIFS(intermediate_workbook_COMPLETE!H:H,">=1501",intermediate_workbook_COMPLETE!H:H,"<=2000") -> 22 | C5: =COUNTIFS(intermediate_workbook_COMPLETE!G:G,">=1501",intermediate_workbook_COMPLETE!G:G,"<=2000") -> 0
A6: 2001-2500 | B6: =COUNTIFS(intermediate_workbook_COMPLETE!H:H,">=2001",intermediate_workbook_COMPLETE!H:H,"<=2500") -> 25 | C6: =COUNTIFS(intermediate_workbook_COMPLETE!G:G,">=2001",intermediate_workbook_COMPLETE!G:G,"<=2500") -> 0
A7: 2501-3000 | B7: =COUNTIFS(intermediate_workbook_COMPLETE!H:H,">=2501",intermediate_workbook_COMPLETE!H:H,"<=3000") -> 7 | C7: =COUNTIFS(intermediate_workbook_COMPLETE!G:G,">=2501",intermediate_workbook_COMPLETE!G:G,"<=3000") -> 0
A8: 3000+ | B8: =COUNTIF(intermediate_workbook_COMPLETE!H:H,">=3000") -> 18 | C8: =COUNTIF(intermediate_workbook_COMPLETE!G:G,">=3000") -> 0

Sheet Chart2_Data
A1: Under 65 Years | B1: 65+ Years
A2: 464.5 | B2: 727
A3: 464.5 | B3: 763
A4: 443 | B4: 769.5
A5: 448 | B5: 754
A6: 499 | B6: 789.5
A7: 510 | B7: 782
A8: 498 | B8: 884
A9: 509.5 | B9: 757
A10: 500 | B10: 940
A11: 432 | B11: 162
A12: 432 | B12: 162
A13: 432 | B13: 162
... A459: 432 | B459: 175

Sheet Chart2_Stats
A1: Statistic | B1: Under 65 Years | C1: 65+ Years
A2: Minimum | B2: =MIN(Chart2_Data!A:A) -> 432 | C2: =MIN(Chart2_Data!B:B) -> 162
A3: Q1 (25%) | B3: =QUARTILE(Chart2_Data!A:A,1) -> 432 | C3: =QUARTILE(Chart2_Data!B:B,1) -> 256.125
A4: Median | B4: =MEDIAN(Chart2_Data!A:A) -> 438.5 | C4: =MEDIAN(Chart2_Data!B:B) -> 571.25
A5: Q3 (75%) | B5: =QUARTILE(Chart2_Data!A:A,3) -> 484.125 | C5: =QUARTILE(Chart2_Data!B:B,3) -> 1115.375
A6: Maximum | B6: =MAX(Chart2_Data!A:A) -> 1311.5 | C6: =MAX(Chart2_Data!B:B) -> 5694
A7: Mean | B7: =AVERAGE(Chart2_Data!A:A) -> 491.91485 | C7: =AVERAGE(Chart2_Data!B:B) -> 891.69105

Sheet Chart3_Data
A1: Pop_Under_65 | B1: Deaths_Under_65 | C1: Pop_65_Plus | D1: Deaths_65_Plus
A2: 4077928.8 | B2: 464.5 | C2: 636565.93 | D2: 727
A3: 4207655.7 | B3: 464.5 | C3: 657917.51 | D3: 763
A4: 4382426.7 | B4: 443 | C4: 698905.82 | D4: 769.5
A5: 4185178 | B5: 448 | C5: 681170.78 | D5: 754
A6: 4179281.4 | B6: 499 | C6: 698711.18 | D6: 789.5
A7: 3956957 | B7: 510 | C7: 664451.93 | D7: 782
A8: 4022073.4 | B8: 498 | C8: 704792.78 | D8: 884
A9: 4173074.8 | B9: 509.5 | C9: 765967.76 | D9: 757
A10: 4010307 | B10: 500 | C10: 751405 | D10: 940
A11: 680233.96 | B11: 432 | C11: 54809.243 | D11: 162
A12: 648359.84 | B12: 432 | C12: 54259.91 | D12: 162
A13: 624306.16 | B13: 432 | C13: 53307.001 | D13: 162
... A459: 535415 | B459: 432 | C459: 92750 | D459: 175

Sheet Chart4_Data
A1: State_Year | B1: Pct_65_Plus | C1: Vax_Rate_65_Plus | D1: Death_Rate_65_Plus | E1: Vax_Category
A2: Alabama_2009 | B2: 13.5 | C2: 67.4 | D2: 114.21
A3: Alabama_2010 | B3: 13.52 | C3: 68.5 | D3: 115.97
A4: Alabama_2011 | B4: 13.75 | C4: 67 | D4: 110.1
A5: Alabama_2012 | B5: 14 | C5: 66.6 | D5: 110.69
A6: Alabama_2013 | B6: 14.32 | C6: 70.6 | D6: 112.99
A7: Alabama_2014 | B7: 14.38 | C7: 65.3 | D7: 117.69
A8: Alabama_2015 | B8: 14.91 | C8: 61.1 | D8: 125.43
A9: Alabama_2016 | B9: 15.51 | C9: 63 | D9: 98.83 | E9: =IF(C2<65,"Low",IF(C2<=70,"Medium","High")) -> Medium
A10: Alabama_2017 | B10: 15.78 | D10: 125.1
A11: Alaska_2009 | B11: 7.46 | C11: 62.6 | D11: 295.57
A12: Alaska_2010 | B12: 7.72 | C12: 55.1 | D12: 298.56
A13: Alaska_2011 | B13: 7.87 | C13: 49.5 | D13: 303.9
A14: Alaska_2012 | B14: 7.88 | C14: 56 | D14: 304.19
A15: Alaska_2013 | B15: 8.72 | C15: 54.3 | D15: 256.59
A16: Alaska_2014 | B16: 8.99 | C16: 57.5 | D16: 278.16
A17: Alaska_2015 | B17: 9.75 | C17: 51.5 | D17: 235.68
A18: Alaska_2016 | B18: 10.47 | C18: 55.6 | D18: 212.43
A19: Alaska_2017 | B19: 10.93 | D19: 202.66
A20: Arizona_2009 | B20: 12.87 | C20: 71.7 | D20: 96.8
A21: Arizona_2010 | B21: 13.35 | C21: 64.3 | D21: 71.08
A22: Arizona_2011 | B22: 13.65 | C22: 58.1 | D22: 64.89
A23: Arizona_2012 | B23: 13.87 | C23: 65.5 | D23: 61.68
A24: Arizona_2013 | B24: 14.31 | C24: 60.5 | D24: 67.34
A25: Arizona_2014 | B25: 14.83 | C25: 62.4 | D25: 60.19
A26: Arizona_2015 | B26: 15.45 | C26: 59.4 | D26: 62.6 | E26: =IF(C19<65,"Low",IF(C19<=70,"Medium","High")) -> Low
A27: Arizona_2016 | B27: 15.45 | C27: 60.8 | D27: 65.92 | E27: =IF(C20<65,"Low",IF(C20<=70,"Medium","High")) -> High
A28: Arizona_2017 | B28: 16.21 | D28: 63.42
A29: Arkansas_2009 | B29: 14.07 | C29: 75.4 | D29: 136.8
A30: Arkansas_2010 | B30: 14.34 | C30: 63.9 | D30: 118.32
A31: Arkansas_2011 | B31: 14.27 | C31: 64.1 | D31: 143.39
A32: Arkansas_2012 | B32: 14.65 | C32: 62.6 | D32: 131.47
A33: Arkansas_2013 | B33: 14.67 | C33: 66.6 | D33: 145.94
A34: Arkansas_2014 | B34: 14.76 | C34: 69.6 | D34: 121.53
A35: Arkansas_2015 | B35: 15.55 | C35: 59.1 | D35: 114.63 | E35: =IF(C28<65,"Low",IF(C28<=70,"Medium","High")) -> Low
A36: Arkansas_2016 | B36: 15.58 | C36: 62.8 | D36: 107.86 | E36: =IF(C29<65,"Low",IF(C29<=70,"Medium","High")) -> High
A37: Arkansas_2017 | B37: 15.75 | D37: 116.29
A38: California_2009 | B38: 10.93 | C38: 71.8 | D38: 130.72
A39: California_2010 | B39: 11.05 | C39: 62.5 | D39: 130.05
A40: California_2011 | B40: 11.3 | C40: 60.7 | D40: 127.55
...

Sheet Table3_Stats
A1: Vaccination Coverage | B1: Number of Observations | C1: Average Death Rate (per 100k) | D1: Median Death Rate (per 100k)
A2: Low (<65%) | B2: =COUNTIF(Chart4_Data!C:C,"<65") -> 150 | C2: =AVERAGEIF(Chart4_Data!C:C,"<65",Chart4_Data!D:D) -> 125.22107 | D2: {=MEDIAN(IF(Chart4_Data!E:E="Low",Chart4_Data!D:D))} -> 111.855
A3: Medium (65-70%) | B3: =COUNTIFS(Chart4_Data!C:C,">=65",Chart4_Data!C:C,"<=70") -> 142 | C3: =AVERAGEIFS(Chart4_Data!D:D,Chart4_Data!C:C,">=65",Chart4_Data!C:C,"<=70") -> 114.60894 | D3: {=MEDIAN(IF((Chart4_Data!C:C>=65)*(Chart4_Data!C:C<=70),Chart4_Data!D:D))} -> 115.73
A4: High (>70%) | B4: =COUNTIF(Chart4_Data!C:C,">70") -> 113 | C4: =AVERAGEIF(Chart4_Data!C:C,">70",Chart4_Data!D:D) -> 127.23035 | D4: {=MEDIAN(IF(Chart4_Data!C:C>70,Chart4_Data!D:D))} -> 122.16
